Workbook

Sheet LÉEME
B2: PEPTIDEX · ESTUDIO DE MERCADO DE PRECIOS DE VENTA
B3: Las 118 presentaciones del catálogo, con el precio al que el mercado las vende hoy y el precio al que conviene venderlas. 02.08.2026
B5: QUÉ HAY EN CADA HOJA
B6: MÉXICO · las 118 presentaciones en pesos. La columna amarilla, PRECIO SUGERIDO, es la respuesta.
B7: USA · las mismas 118 en dólares.
B8: BANDAS · el motor. La banda de precio por unidad de cada compuesto, con su fuente. Cambiar un número aquí actualiza las dos hojas de arriba.
B9: FUENTES · cada enlace consultado y qué dato salió de él.
B11: CÓMO SE LLEGA AL PRECIO SUGERIDO
B12: 1 · Se busca el precio real de cada compuesto en el mercado y se expresa por unidad — por mg casi siempre, por UI en la hormona de crecimiento y por ml en el lipotrópico.
B13: 2 · Esa banda por unidad se multiplica por la cantidad de cada presentación. Así el vial de 20 mg sale del mismo número que el de 5 mg, que es como se comporta el mercado.
B14: 3 · El sugerido es el punto medio de la banda, redondeado. Ni el suelo — que es guerra de precio — ni el techo, que sólo lo sostiene una marca ya conocida.
B16: LO QUE HAY QUE MIRAR PRIMERO
... B27: Research Use Only — no para uso humano ni veterinario.

Sheet MÉXICO
B2: PEPTIDEX · PRECIOS DE VENTA — MÉXICO
B3: Precio de mercado y precio sugerido para las 118 presentaciones. La columna amarilla es la respuesta. 02.08.2026
A5: LÍNEA | B5: CÓDIGO | C5: COMPUESTO | D5: CANT. | E5: UNIDAD | F5: TU PRECIO HOY | G5: MERCADO BAJO | H5: MERCADO ALTO | I5: PRECIO SUGERIDO | J5: PRECIO POR UNIDAD | K5: ¿DÓNDE QUEDAS? | L5: CONF. | M5: COMPETIDOR REAL | N5: QUIÉN
A6: BEAUTY | B6: AC | C6: AHK-Cu | D6: 20 | E6: mg | F6: 500 | G6: =BANDAS!$E$9*$D6*BANDAS!$E$5*BANDAS!$E$6 | H6: =BANDAS!$F$9*$D6*BANDAS!$E$5*BANDAS!$E$6 | I6: =ROUND(AVERAGE(G6,H6)/50,0)*50 | J6: =IF($D6=0,"",I6/$D6) | K6: =IF(F6="","",IF(F6<G6,"POR DEBAJO",IF(F6>H6,"POR ENCIMA","EN MERCADO"))) | L6: D
A7: BEAUTY | B7: AC | C7: AHK-Cu | D7: 50 | E7: mg | F7: 1350 | G7: =BANDAS!$E$9*$D7*BANDAS!$E$5*BANDAS!$E$6 | H7: =BANDAS!$F$9*$D7*BANDAS!$E$5*BANDAS!$E$6 | I7: =ROUND(AVERAGE(G7,H7)/50,0)*50 | J7: =IF($D7=0,"",I7/$D7) | K7: =IF(F7="","",IF(F7<G7,"POR DEBAJO",IF(F7>H7,"POR ENCIMA","EN MERCADO"))) | L7: D
A8: BEAUTY | B8: CU | C8: GHK-Cu | D8: 50 | E8: mg | F8: 1150 | G8: =BANDAS!$E$10*$D8*BANDAS!$E$5*BANDAS!$E$6 | H8: =BANDAS!$F$10*$D8*BANDAS!$E$5*BANDAS!$E$6 | I8: =ROUND(AVERAGE(G8,H8)/50,0)*50 | J8: =IF($D8=0,"",I8/$D8) | K8: =IF(F8="","",IF(F8<G8,"POR DEBAJO",IF(F8>H8,"POR ENCIMA","EN MERCADO"))) | L8: V | M8: 520 | N8: EXOMA Peptides
A9: BEAUTY | B9: CU | C9: GHK-Cu | D9: 100 | E9: mg | F9: 1850 | G9: =BANDAS!$E$10*$D9*BANDAS!$E$5*BANDAS!$E$6 | H9: =BANDAS!$F$10*$D9*BANDAS!$E$5*BANDAS!$E$6 | I9: =ROUND(AVERAGE(G9,H9)/50,0)*50 | J9: =IF($D9=0,"",I9/$D9) | K9: =IF(F9="","",IF(F9<G9,"POR DEBAJO",IF(F9>H9,"POR ENCIMA","EN MERCADO"))) | L9: V
A10: BEAUTY | B10: GL | C10: GLOW Blend | D10: 70 | E10: mg | F10: 6400 | G10: =BANDAS!$E$11*$D10*BANDAS!$E$5*BANDAS!$E$6 | H10: =BANDAS!$F$11*$D10*BANDAS!$E$5*BANDAS!$E$6 | I10: =ROUND(AVERAGE(G10,H10)/50,0)*50 | J10: =IF($D10=0,"",I10/$D10) | K10: =IF(F10="","",IF(F10<G10,"POR DEBAJO",IF(F10>H10,"POR ENCIMA","EN MERCADO"))) | L10: D | M10: 2090 | N10: EXOMA Peptides
A11: BEAUTY | B11: GT | C11: Glutathione | D11: 600 | E11: mg | F11: 1100 | G11: =BANDAS!$E$12*$D11*BANDAS!$E$5*BANDAS!$E$6 | H11: =BANDAS!$F$12*$D11*BANDAS!$E$5*BANDAS!$E$6 | I11: =ROUND(AVERAGE(G11,H11)/50,0)*50 | J11: =IF($D11=0,"",I11/$D11) | K11: =IF(F11="","",IF(F11<G11,"POR DEBAJO",IF(F11>H11,"POR ENCIMA","EN MERCADO"))) | L11: D
A12: BEAUTY | B12: GT | C12: Glutathione | D12: 1500 | E12: mg | F12: 2700 | G12: =BANDAS!$E$12*$D12*BANDAS!$E$5*BANDAS!$E$6 | H12: =BANDAS!$F$12*$D12*BANDAS!$E$5*BANDAS!$E$6 | I12: =ROUND(AVERAGE(G12,H12)/50,0)*50 | J12: =IF($D12=0,"",I12/$D12) | K12: =IF(F12="","",IF(F12<G12,"POR DEBAJO",IF(F12>H12,"POR ENCIMA","EN MERCADO"))) | L12: D
A13: BEAUTY | B13: KL | C13: KLOW Blend | D13: 80 | E13: mg | F13: 7400 | G13: =BANDAS!$E$13*$D13*BANDAS!$E$5*BANDAS!$E$6 | H13: =BANDAS!$F$13*$D13*BANDAS!$E$5*BANDAS!$E$6 | I13: =ROUND(AVERAGE(G13,H13)/50,0)*50 | J13: =IF($D13=0,"",I13/$D13) | K13: =IF(F13="","",IF(F13<G13,"POR DEBAJO",IF(F13>H13,"POR ENCIMA","EN MERCADO"))) | L13: D
A14: BEAUTY | B14: KP | C14: KPV | D14: 5 | E14: mg | F14: 500 | G14: =BANDAS!$E$14*$D14*BANDAS!$E$5*BANDAS!$E$6 | H14: =BANDAS!$F$14*$D14*BANDAS!$E$5*BANDAS!$E$6 | I14: =ROUND(AVERAGE(G14,H14)/50,0)*50 | J14: =IF($D14=0,"",I14/$D14) | K14: =IF(F14="","",IF(F14<G14,"POR DEBAJO",IF(F14>H14,"POR ENCIMA","EN MERCADO"))) | L14: D
A15: BEAUTY | B15: KP | C15: KPV | D15: 10 | E15: mg | F15: 850 | G15: =BANDAS!$E$14*$D15*BANDAS!$E$5*BANDAS!$E$6 | H15: =BANDAS!$F$14*$D15*BANDAS!$E$5*BANDAS!$E$6 | I15: =ROUND(AVERAGE(G15,H15)/50,0)*50 | J15: =IF($D15=0,"",I15/$D15) | K15: =IF(F15="","",IF(F15<G15,"POR DEBAJO",IF(F15>H15,"POR ENCIMA","EN MERCADO"))) | L15: D
A16: BEAUTY | B16: MX | C16: Matrixyl | D16: 10 | E16: mg | F16: 2100 | G16: =BANDAS!$E$15*$D16*BANDAS!$E$5*BANDAS!$E$6 | H16: =BANDAS!$F$15*$D16*BANDAS!$E$5*BANDAS!$E$6 | I16: =ROUND(AVERAGE(G16,H16)/50,0)*50 | J16: =IF($D16=0,"",I16/$D16) | K16: =IF(F16="","",IF(F16<G16,"POR DEBAJO",IF(F16>H16,"POR ENCIMA","EN MERCADO"))) | L16: D
A17: BEAUTY | B17: MT1 | C17: Melanotan I | D17: 10 | E17: mg | F17: 1000 | G17: =BANDAS!$E$16*$D17*BANDAS!$E$5*BANDAS!$E$6 | H17: =BANDAS!$F$16*$D17*BANDAS!$E$5*BANDAS!$E$6 | I17: =ROUND(AVERAGE(G17,H17)/50,0)*50 | J17: =IF($D17=0,"",I17/$D17) | K17: =IF(F17="","",IF(F17<G17,"POR DEBAJO",IF(F17>H17,"POR ENCIMA","EN MERCADO"))) | L17: D
A18: BEAUTY | B18: MT2 | C18: Melanotan II | D18: 10 | E18: mg | F18: 1000 | G18: =BANDAS!$E$17*$D18*BANDAS!$E$5*BANDAS!$E$6 | H18: =BANDAS!$F$17*$D18*BANDAS!$E$5*BANDAS!$E$6 | I18: =ROUND(AVERAGE(G18,H18)/50,0)*50 | J18: =IF($D18=0,"",I18/$D18) | K18: =IF(F18="","",IF(F18<G18,"POR DEBAJO",IF(F18>H18,"POR ENCIMA","EN MERCADO"))) | L18: V
A19: BEAUTY | B19: OT | C19: Oxytocin | D19: 5 | E19: mg | F19: 1000 | G19: =BANDAS!$E$18*$D19*BANDAS!$E$5*BANDAS!$E$6 | H19: =BANDAS!$F$18*$D19*BANDAS!$E$5*BANDAS!$E$6 | I19: =ROUND(AVERAGE(G19,H19)/50,0)*50 | J19: =IF($D19=0,"",I19/$D19) | K19: =IF(F19="","",IF(F19<G19,"POR DEBAJO",IF(F19>H19,"POR ENCIMA","EN MERCADO"))) | L19: D
A20: BEAUTY | B20: PT | C20: PT-141 | D20: 10 | E20: mg | F20: 1000 | G20: =BANDAS!$E$19*$D20*BANDAS!$E$5*BANDAS!$E$6 | H20: =BANDAS!$F$19*$D20*BANDAS!$E$5*BANDAS!$E$6 | I20: =ROUND(AVERAGE(G20,H20)/50,0)*50 | J20: =IF($D20=0,"",I20/$D20) | K20: =IF(F20="","",IF(F20<G20,"POR DEBAJO",IF(F20>H20,"POR ENCIMA","EN MERCADO"))) | L20: V
A21: BEAUTY | B21: NP8 | C21: Snap-8 | D21: 10 | E21: mg | F21: 850 | G21: =BANDAS!$E$20*$D21*BANDAS!$E$5*BANDAS!$E$6 | H21: =BANDAS!$F$20*$D21*BANDAS!$E$5*BANDAS!$E$6 | I21: =ROUND(AVERAGE(G21,H21)/50,0)*50 | J21: =IF($D21=0,"",I21/$D21) | K21: =IF(F21="","",IF(F21<G21,"POR DEBAJO",IF(F21>H21,"POR ENCIMA","EN MERCADO"))) | L21: D
A22: FITNESS | B22: AM | C22: 5-Amino-1MQ | D22: 5 | E22: mg | F22: 300 | G22: =BANDAS!$E$21*$D22*BANDAS!$E$5*BANDAS!$E$6 | H22: =BANDAS!$F$21*$D22*BANDAS!$E$5*BANDAS!$E$6 | I22: =ROUND(AVERAGE(G22,H22)/50,0)*50 | J22: =IF($D22=0,"",I22/$D22) | K22: =IF(F22="","",IF(F22<G22,"POR DEBAJO",IF(F22>H22,"POR ENCIMA","EN MERCADO"))) | L22: D
A23: FITNESS | B23: AM | C23: 5-Amino-1MQ | D23: 10 | E23: mg | F23: 550 | G23: =BANDAS!$E$21*$D23*BANDAS!$E$5*BANDAS!$E$6 | H23: =BANDAS!$F$21*$D23*BANDAS!$E$5*BANDAS!$E$6 | I23: =ROUND(AVERAGE(G23,H23)/50,0)*50 | J23: =IF($D23=0,"",I23/$D23) | K23: =IF(F23="","",IF(F23<G23,"POR DEBAJO",IF(F23>H23,"POR ENCIMA","EN MERCADO"))) | L23: D
A24: FITNESS | B24: AM | C24: 5-Amino-1MQ | D24: 50 | E24: mg | F24: 2350 | G24: =BANDAS!$E$21*$D24*BANDAS!$E$5*BANDAS!$E$6 | H24: =BANDAS!$F$21*$D24*BANDAS!$E$5*BANDAS!$E$6 | I24: =ROUND(AVERAGE(G24,H24)/50,0)*50 | J24: =IF($D24=0,"",I24/$D24) | K24: =IF(F24="","",IF(F24<G24,"POR DEBAJO",IF(F24>H24,"POR ENCIMA","EN MERCADO"))) | L24: D
A25: FITNESS | B25: AR | C25: AICAR | D25: 50 | E25: mg | F25: 1350 | G25: =BANDAS!$E$22*$D25*BANDAS!$E$5*BANDAS!$E$6 | H25: =BANDAS!$F$22*$D25*BANDAS!$E$5*BANDAS!$E$6 | I25: =ROUND(AVERAGE(G25,H25)/50,0)*50 | J25: =IF($D25=0,"",I25/$D25) | K25: =IF(F25="","",IF(F25<G25,"POR DEBAJO",IF(F25>H25,"POR ENCIMA","EN MERCADO"))) | L25: D
A26: FITNESS | B26: AR | C26: AICAR | D26: 100 | E26: mg | F26: 2700 | G26: =BANDAS!$E$22*$D26*BANDAS!$E$5*BANDAS!$E$6 | H26: =BANDAS!$F$22*$D26*BANDAS!$E$5*BANDAS!$E$6 | I26: =ROUND(AVERAGE(G26,H26)/50,0)*50 | J26: =IF($D26=0,"",I26/$D26) | K26: =IF(F26="","",IF(F26<G26,"POR DEBAJO",IF(F26>H26,"POR ENCIMA","EN MERCADO"))) | L26: D
A27: FITNESS | B27: AD | C27: AOD-9604 | D27: 5 | E27: mg | F27: 800 | G27: =BANDAS!$E$23*$D27*BANDAS!$E$5*BANDAS!$E$6 | H27: =BANDAS!$F$23*$D27*BANDAS!$E$5*BANDAS!$E$6 | I27: =ROUND(AVERAGE(G27,H27)/50,0)*50 | J27: =IF($D27=0,"",I27/$D27) | K27: =IF(F27="","",IF(F27<G27,"POR DEBAJO",IF(F27>H27,"POR ENCIMA","EN MERCADO"))) | L27: D
A28: FITNESS | B28: AD | C28: AOD-9604 | D28: 10 | E28: mg | F28: 1450 | G28: =BANDAS!$E$23*$D28*BANDAS!$E$5*BANDAS!$E$6 | H28: =BANDAS!$F$23*$D28*BANDAS!$E$5*BANDAS!$E$6 | I28: =ROUND(AVERAGE(G28,H28)/50,0)*50 | J28: =IF($D28=0,"",I28/$D28) | K28: =IF(F28="","",IF(F28<G28,"POR DEBAJO",IF(F28>H28,"POR ENCIMA","EN MERCADO"))) | L28: D
A29: FITNESS | B29: AX | C29: Adamax | D29: 10 | E29: mg | F29: 2100 | G29: =BANDAS!$E$24*$D29*BANDAS!$E$5*BANDAS!$E$6 | H29: =BANDAS!$F$24*$D29*BANDAS!$E$5*BANDAS!$E$6 | I29: =ROUND(AVERAGE(G29,H29)/50,0)*50 | J29: =IF($D29=0,"",I29/$D29) | K29: =IF(F29="","",IF(F29<G29,"POR DEBAJO",IF(F29>H29,"POR ENCIMA","EN MERCADO"))) | L29: D
A30: FITNESS | B30: APT | C30: Adipotide | D30: 5 | E30: mg | F30: 1000 | G30: =BANDAS!$E$25*$D30*BANDAS!$E$5*BANDAS!$E$6 | H30: =BANDAS!$F$25*$D30*BANDAS!$E$5*BANDAS!$E$6 | I30: =ROUND(AVERAGE(G30,H30)/50,0)*50 | J30: =IF($D30=0,"",I30/$D30) | K30: =IF(F30="","",IF(F30<G30,"POR DEBAJO",IF(F30>H30,"POR ENCIMA","EN MERCADO"))) | L30: D
A31: FITNESS | B31: APT | C31: Adipotide | D31: 10 | E31: mg | F31: 2100 | G31: =BANDAS!$E$25*$D31*BANDAS!$E$5*BANDAS!$E$6 | H31: =BANDAS!$F$25*$D31*BANDAS!$E$5*BANDAS!$E$6 | I31: =ROUND(AVERAGE(G31,H31)/50,0)*50 | J31: =IF($D31=0,"",I31/$D31) | K31: =IF(F31="","",IF(F31<G31,"POR DEBAJO",IF(F31>H31,"POR ENCIMA","EN MERCADO"))) | L31: D
A32: FITNESS | B32: RA | C32: Ara-290 | D32: 10 | E32: mg | F32: 2100 | G32: =BANDAS!$E$26*$D32*BANDAS!$E$5*BANDAS!$E$6 | H32: =BANDAS!$F$26*$D32*BANDAS!$E$5*BANDAS!$E$6 | I32: =ROUND(AVERAGE(G32,H32)/50,0)*50 | J32: =IF($D32=0,"",I32/$D32) | K32: =IF(F32="","",IF(F32<G32,"POR DEBAJO",IF(F32>H32,"POR ENCIMA","EN MERCADO"))) | L32: D
A33: FITNESS | B33: BC | C33: BPC-157 | D33: 5 | E33: mg | F33: 700 | G33: =BANDAS!$E$27*$D33*BANDAS!$E$5*BANDAS!$E$6 | H33: =BANDAS!$F$27*$D33*BANDAS!$E$5*BANDAS!$E$6 | I33: =ROUND(AVERAGE(G33,H33)/50,0)*50 | J33: =IF($D33=0,"",I33/$D33) | K33: =IF(F33="","",IF(F33<G33,"POR DEBAJO",IF(F33>H33,"POR ENCIMA","EN MERCADO"))) | L33: V | M33: 610 | N33: EXOMA Peptides
A34: FITNESS | B34: BC | C34: BPC-157 | D34: 10 | E34: mg | F34: 1050 | G34: =BANDAS!$E$27*$D34*BANDAS!$E$5*BANDAS!$E$6 | H34: =BANDAS!$F$27*$D34*BANDAS!$E$5*BANDAS!$E$6 | I34: =ROUND(AVERAGE(G34,H34)/50,0)*50 | J34: =IF($D34=0,"",I34/$D34) | K34: =IF(F34="","",IF(F34<G34,"POR DEBAJO",IF(F34>H34,"POR ENCIMA","EN MERCADO"))) | L34: V
A35: FITNESS | B35: BC | C35: BPC-157 | D35: 20 | E35: mg | F35: 1850 | G35: =BANDAS!$E$27*$D35*BANDAS!$E$5*BANDAS!$E$6 | H35: =BANDAS!$F$27*$D35*BANDAS!$E$5*BANDAS!$E$6 | I35: =ROUND(AVERAGE(G35,H35)/50,0)*50 | J35: =IF($D35=0,"",I35/$D35) | K35: =IF(F35="","",IF(F35<G35,"POR DEBAJO",IF(F35>H35,"POR ENCIMA","EN MERCADO"))) | L35: V
A36: FITNESS | B36: BB | C36: BPC-157 + TB-500 | D36: 10 | E36: mg | F36: 2850 | G36: =BANDAS!$E$28*$D36*BANDAS!$E$5*BANDAS!$E$6 | H36: =BANDAS!$F$28*$D36*BANDAS!$E$5*BANDAS!$E$6 | I36: =ROUND(AVERAGE(G36,H36)/50,0)*50 | J36: =IF($D36=0,"",I36/$D36) | K36: =IF(F36="","",IF(F36<G36,"POR DEBAJO",IF(F36>H36,"POR ENCIMA","EN MERCADO"))) | L36: D | M36: 1399 | N36: EXOMA Peptides
A37: FITNESS | B37: BB | C37: BPC-157 + TB-500 | D37: 20 | E37: mg | F37: 3200 | G37: =BANDAS!$E$28*$D37*BANDAS!$E$5*BANDAS!$E$6 | H37: =BANDAS!$F$28*$D37*BANDAS!$E$5*BANDAS!$E$6 | I37: =ROUND(AVERAGE(G37,H37)/50,0)*50 | J37: =IF($D37=0,"",I37/$D37) | K37: =IF(F37="","",IF(F37<G37,"POR DEBAJO",IF(F37>H37,"POR ENCIMA","EN MERCADO"))) | L37: D
A38: FITNESS | B38: CD | C38: CJC-1295 (DAC) | D38: 5 | E38: mg | F38: 1150 | G38: =BANDAS!$E$29*$D38*BANDAS!$E$5*BANDAS!$E$6 | H38: =BANDAS!$F$29*$D38*BANDAS!$E$5*BANDAS!$E$6 | I38: =ROUND(AVERAGE(G38,H38)/50,0)*50 | J38: =IF($D38=0,"",I38/$D38) | K38: =IF(F38="","",IF(F38<G38,"POR DEBAJO",IF(F38>H38,"POR ENCIMA","EN MERCADO"))) | L38: D
A39: FITNESS | B39: CD | C39: CJC-1295 (DAC) | D39: 10 | E39: mg | F39: 2150 | G39: =BANDAS!$E$29*$D39*BANDAS!$E$5*BANDAS!$E$6 | H39: =BANDAS!$F$29*$D39*BANDAS!$E$5*BANDAS!$E$6 | I39: =ROUND(AVERAGE(G39,H39)/50,0)*50 | J39: =IF($D39=0,"",I39/$D39) | K39: =IF(F39="","",IF(F39<G39,"POR DEBAJO",IF(F39>H39,"POR ENCIMA","EN MERCADO"))) | L39: D
A40: FITNESS | B40: CN | C40: CJC-1295 (no DAC) | D40: 5 | E40: mg | F40: 650 | G40: =BANDAS!$E$30*$D40*BANDAS!$E$5*BANDAS!$E$6 | H40: =BANDAS!$F$30*$D40*BANDAS!$E$5*BANDAS!$E$6 | I40: =ROUND(AVERAGE(G40,H40)/50,0)*50 | J40: =IF($D40=0,"",I40/$D40) | K40: =IF(F40="","",IF(F40<G40,"POR DEBAJO",IF(F40>H40,"POR ENCIMA","EN MERCADO"))) | L40: D
A41: FITNESS | B41: CN | C41: CJC-1295 (no DAC) | D41: 10 | E41: mg | F41: 1250 | G41: =BANDAS!$E$30*$D41*BANDAS!$E$5*BANDAS!$E$6 | H41: =BANDAS!$F$30*$D41*BANDAS!$E$5*BANDAS!$E$6 | I41: =ROUND(AVERAGE(G41,H41)/50,0)*50 | J41: =IF($D41=0,"",I41/$D41) | K41: =IF(F41="","",IF(F41<G41,"POR DEBAJO",IF(F41>H41,"POR ENCIMA","EN MERCADO"))) | L41: D
A42: FITNESS | B42: CP | C42: CJC-1295 + Ipamorelin | D42: 10 | E42: mg | F42: 1250 | G42: =BANDAS!$E$31*$D42*BANDAS!$E$5*BANDAS!$E$6 | H42: =BANDAS!$F$31*$D42*BANDAS!$E$5*BANDAS!$E$6 | I42: =ROUND(AVERAGE(G42,H42)/50,0)*50 | J42: =IF($D42=0,"",I42/$D42) | K42: =IF(F42="","",IF(F42<G42,"POR DEBAJO",IF(F42>H42,"POR ENCIMA","EN MERCADO"))) | L42: V
...

Sheet USA
B2: PEPTIDEX · PRECIOS DE VENTA — USA
B3: Precio de mercado y precio sugerido para las 118 presentaciones. La columna amarilla es la respuesta. 02.08.2026
A5: LÍNEA | B5: CÓDIGO | C5: COMPUESTO | D5: CANT. | E5: UNIDAD | F5: TU PRECIO HOY | G5: MERCADO BAJO | H5: MERCADO ALTO | I5: PRECIO SUGERIDO | J5: PRECIO POR UNIDAD | K5: ¿DÓNDE QUEDAS? | L5: CONF.
A6: BEAUTY | B6: AC | C6: AHK-Cu | D6: 20 | E6: mg | F6: 20 | G6: =BANDAS!$E$9*$D6 | H6: =BANDAS!$F$9*$D6 | I6: =ROUND(AVERAGE(G6,H6)/1,0)*1 | J6: =IF($D6=0,"",I6/$D6) | K6: =IF(F6="","",IF(F6<G6,"POR DEBAJO",IF(F6>H6,"POR ENCIMA","EN MERCADO"))) | L6: D
A7: BEAUTY | B7: AC | C7: AHK-Cu | D7: 50 | E7: mg | F7: 55 | G7: =BANDAS!$E$9*$D7 | H7: =BANDAS!$F$9*$D7 | I7: =ROUND(AVERAGE(G7,H7)/1,0)*1 | J7: =IF($D7=0,"",I7/$D7) | K7: =IF(F7="","",IF(F7<G7,"POR DEBAJO",IF(F7>H7,"POR ENCIMA","EN MERCADO"))) | L7: D
A8: BEAUTY | B8: CU | C8: GHK-Cu | D8: 50 | E8: mg | F8: 35 | G8: =BANDAS!$E$10*$D8 | H8: =BANDAS!$F$10*$D8 | I8: =ROUND(AVERAGE(G8,H8)/1,0)*1 | J8: =IF($D8=0,"",I8/$D8) | K8: =IF(F8="","",IF(F8<G8,"POR DEBAJO",IF(F8>H8,"POR ENCIMA","EN MERCADO"))) | L8: V
A9: BEAUTY | B9: CU | C9: GHK-Cu | D9: 100 | E9: mg | F9: 75 | G9: =BANDAS!$E$10*$D9 | H9: =BANDAS!$F$10*$D9 | I9: =ROUND(AVERAGE(G9,H9)/1,0)*1 | J9: =IF($D9=0,"",I9/$D9) | K9: =IF(F9="","",IF(F9<G9,"POR DEBAJO",IF(F9>H9,"POR ENCIMA","EN MERCADO"))) | L9: V
A10: BEAUTY | B10: GL | C10: GLOW Blend | D10: 70 | E10: mg | F10: 260 | G10: =BANDAS!$E$11*$D10 | H10: =BANDAS!$F$11*$D10 | I10: =ROUND(AVERAGE(G10,H10)/1,0)*1 | J10: =IF($D10=0,"",I10/$D10) | K10: =IF(F10="","",IF(F10<G10,"POR DEBAJO",IF(F10>H10,"POR ENCIMA","EN MERCADO"))) | L10: D
A11: BEAUTY | B11: GT | C11: Glutathione | D11: 600 | E11: mg | F11: 45 | G11: =BANDAS!$E$12*$D11 | H11: =BANDAS!$F$12*$D11 | I11: =ROUND(AVERAGE(G11,H11)/1,0)*1 | J11: =IF($D11=0,"",I11/$D11) | K11: =IF(F11="","",IF(F11<G11,"POR DEBAJO",IF(F11>H11,"POR ENCIMA","EN MERCADO"))) | L11: D
A12: BEAUTY | B12: GT | C12: Glutathione | D12: 1500 | E12: mg | F12: 110 | G12: =BANDAS!$E$12*$D12 | H12: =BANDAS!$F$12*$D12 | I12: =ROUND(AVERAGE(G12,H12)/1,0)*1 | J12: =IF($D12=0,"",I12/$D12) | K12: =IF(F12="","",IF(F12<G12,"POR DEBAJO",IF(F12>H12,"POR ENCIMA","EN MERCADO"))) | L12: D
A13: BEAUTY | B13: KL | C13: KLOW Blend | D13: 80 | E13: mg | F13: 300 | G13: =BANDAS!$E$13*$D13 | H13: =BANDAS!$F$13*$D13 | I13: =ROUND(AVERAGE(G13,H13)/1,0)*1 | J13: =IF($D13=0,"",I13/$D13) | K13: =IF(F13="","",IF(F13<G13,"POR DEBAJO",IF(F13>H13,"POR ENCIMA","EN MERCADO"))) | L13: D
A14: BEAUTY | B14: KP | C14: KPV | D14: 5 | E14: mg | F14: 20 | G14: =BANDAS!$E$14*$D14 | H14: =BANDAS!$F$14*$D14 | I14: =ROUND(AVERAGE(G14,H14)/1,0)*1 | J14: =IF($D14=0,"",I14/$D14) | K14: =IF(F14="","",IF(F14<G14,"POR DEBAJO",IF(F14>H14,"POR ENCIMA","EN MERCADO"))) | L14: D
A15: BEAUTY | B15: KP | C15: KPV | D15: 10 | E15: mg | F15: 35 | G15: =BANDAS!$E$14*$D15 | H15: =BANDAS!$F$14*$D15 | I15: =ROUND(AVERAGE(G15,H15)/1,0)*1 | J15: =IF($D15=0,"",I15/$D15) | K15: =IF(F15="","",IF(F15<G15,"POR DEBAJO",IF(F15>H15,"POR ENCIMA","EN MERCADO"))) | L15: D
A16: BEAUTY | B16: MX | C16: Matrixyl | D16: 10 | E16: mg | F16: 85 | G16: =BANDAS!$E$15*$D16 | H16: =BANDAS!$F$15*$D16 | I16: =ROUND(AVERAGE(G16,H16)/1,0)*1 | J16: =IF($D16=0,"",I16/$D16) | K16: =IF(F16="","",IF(F16<G16,"POR DEBAJO",IF(F16>H16,"POR ENCIMA","EN MERCADO"))) | L16: D
A17: BEAUTY | B17: MT1 | C17: Melanotan I | D17: 10 | E17: mg | F17: 40 | G17: =BANDAS!$E$16*$D17 | H17: =BANDAS!$F$16*$D17 | I17: =ROUND(AVERAGE(G17,H17)/1,0)*1 | J17: =IF($D17=0,"",I17/$D17) | K17: =IF(F17="","",IF(F17<G17,"POR DEBAJO",IF(F17>H17,"POR ENCIMA","EN MERCADO"))) | L17: D
A18: BEAUTY | B18: MT2 | C18: Melanotan II | D18: 10 | E18: mg | F18: 40 | G18: =BANDAS!$E$17*$D18 | H18: =BANDAS!$F$17*$D18 | I18: =ROUND(AVERAGE(G18,H18)/1,0)*1 | J18: =IF($D18=0,"",I18/$D18) | K18: =IF(F18="","",IF(F18<G18,"POR DEBAJO",IF(F18>H18,"POR ENCIMA","EN MERCADO"))) | L18: V
A19: BEAUTY | B19: OT | C19: Oxytocin | D19: 5 | E19: mg | F19: 40 | G19: =BANDAS!$E$18*$D19 | H19: =BANDAS!$F$18*$D19 | I19: =ROUND(AVERAGE(G19,H19)/1,0)*1 | J19: =IF($D19=0,"",I19/$D19) | K19: =IF(F19="","",IF(F19<G19,"POR DEBAJO",IF(F19>H19,"POR ENCIMA","EN MERCADO"))) | L19: D
A20: BEAUTY | B20: PT | C20: PT-141 | D20: 10 | E20: mg | F20: 40 | G20: =BANDAS!$E$19*$D20 | H20: =BANDAS!$F$19*$D20 | I20: =ROUND(AVERAGE(G20,H20)/1,0)*1 | J20: =IF($D20=0,"",I20/$D20) | K20: =IF(F20="","",IF(F20<G20,"POR DEBAJO",IF(F20>H20,"POR ENCIMA","EN MERCADO"))) | L20: V
A21: BEAUTY | B21: NP8 | C21: Snap-8 | D21: 10 | E21: mg | F21: 35 | G21: =BANDAS!$E$20*$D21 | H21: =BANDAS!$F$20*$D21 | I21: =ROUND(AVERAGE(G21,H21)/1,0)*1 | J21: =IF($D21=0,"",I21/$D21) | K21: =IF(F21="","",IF(F21<G21,"POR DEBAJO",IF(F21>H21,"POR ENCIMA","EN MERCADO"))) | L21: D
A22: FITNESS | B22: AM | C22: 5-Amino-1MQ | D22: 5 | E22: mg | F22: 12 | G22: =BANDAS!$E$21*$D22 | H22: =BANDAS!$F$21*$D22 | I22: =ROUND(AVERAGE(G22,H22)/1,0)*1 | J22: =IF($D22=0,"",I22/$D22) | K22: =IF(F22="","",IF(F22<G22,"POR DEBAJO",IF(F22>H22,"POR ENCIMA","EN MERCADO"))) | L22: D
A23: FITNESS | B23: AM | C23: 5-Amino-1MQ | D23: 10 | E23: mg | F23: 21 | G23: =BANDAS!$E$21*$D23 | H23: =BANDAS!$F$21*$D23 | I23: =ROUND(AVERAGE(G23,H23)/1,0)*1 | J23: =IF($D23=0,"",I23/$D23) | K23: =IF(F23="","",IF(F23<G23,"POR DEBAJO",IF(F23>H23,"POR ENCIMA","EN MERCADO"))) | L23: D
A24: FITNESS | B24: AM | C24: 5-Amino-1MQ | D24: 50 | E24: mg | F24: 95 | G24: =BANDAS!$E$21*$D24 | H24: =BANDAS!$F$21*$D24 | I24: =ROUND(AVERAGE(G24,H24)/1,0)*1 | J24: =IF($D24=0,"",I24/$D24) | K24: =IF(F24="","",IF(F24<G24,"POR DEBAJO",IF(F24>H24,"POR ENCIMA","EN MERCADO"))) | L24: D
A25: FITNESS | B25: AR | C25: AICAR | D25: 50 | E25: mg | F25: 55 | G25: =BANDAS!$E$22*$D25 | H25: =BANDAS!$F$22*$D25 | I25: =ROUND(AVERAGE(G25,H25)/1,0)*1 | J25: =IF($D25=0,"",I25/$D25) | K25: =IF(F25="","",IF(F25<G25,"POR DEBAJO",IF(F25>H25,"POR ENCIMA","EN MERCADO"))) | L25: D
A26: FITNESS | B26: AR | C26: AICAR | D26: 100 | E26: mg | F26: 110 | G26: =BANDAS!$E$22*$D26 | H26: =BANDAS!$F$22*$D26 | I26: =ROUND(AVERAGE(G26,H26)/1,0)*1 | J26: =IF($D26=0,"",I26/$D26) | K26: =IF(F26="","",IF(F26<G26,"POR DEBAJO",IF(F26>H26,"POR ENCIMA","EN MERCADO"))) | L26: D
A27: FITNESS | B27: AD | C27: AOD-9604 | D27: 5 | E27: mg | F27: 31 | G27: =BANDAS!$E$23*$D27 | H27: =BANDAS!$F$23*$D27 | I27: =ROUND(AVERAGE(G27,H27)/1,0)*1 | J27: =IF($D27=0,"",I27/$D27) | K27: =IF(F27="","",IF(F27<G27,"POR DEBAJO",IF(F27>H27,"POR ENCIMA","EN MERCADO"))) | L27: D
A28: FITNESS | B28: AD | C28: AOD-9604 | D28: 10 | E28: mg | F28: 56 | G28: =BANDAS!$E$23*$D28 | H28: =BANDAS!$F$23*$D28 | I28: =ROUND(AVERAGE(G28,H28)/1,0)*1 | J28: =IF($D28=0,"",I28/$D28) | K28: =IF(F28="","",IF(F28<G28,"POR DEBAJO",IF(F28>H28,"POR ENCIMA","EN MERCADO"))) | L28: D
A29: FITNESS | B29: AX | C29: Adamax | D29: 10 | E29: mg | F29: 85 | G29: =BANDAS!$E$24*$D29 | H29: =BANDAS!$F$24*$D29 | I29: =ROUND(AVERAGE(G29,H29)/1,0)*1 | J29: =IF($D29=0,"",I29/$D29) | K29: =IF(F29="","",IF(F29<G29,"POR DEBAJO",IF(F29>H29,"POR ENCIMA","EN MERCADO"))) | L29: D
A30: FITNESS | B30: APT | C30: Adipotide | D30: 5 | E30: mg | F30: 40 | G30: =BANDAS!$E$25*$D30 | H30: =BANDAS!$F$25*$D30 | I30: =ROUND(AVERAGE(G30,H30)/1,0)*1 | J30: =IF($D30=0,"",I30/$D30) | K30: =IF(F30="","",IF(F30<G30,"POR DEBAJO",IF(F30>H30,"POR ENCIMA","EN MERCADO"))) | L30: D
A31: FITNESS | B31: APT | C31: Adipotide | D31: 10 | E31: mg | F31: 85 | G31: =BANDAS!$E$25*$D31 | H31: =BANDAS!$F$25*$D31 | I31: =ROUND(AVERAGE(G31,H31)/1,0)*1 | J31: =IF($D31=0,"",I31/$D31) | K31: =IF(F31="","",IF(F31<G31,"POR DEBAJO",IF(F31>H31,"POR ENCIMA","EN MERCADO"))) | L31: D
A32: FITNESS | B32: RA | C32: Ara-290 | D32: 10 | E32: mg | F32: 85 | G32: =BANDAS!$E$26*$D32 | H32: =BANDAS!$F$26*$D32 | I32: =ROUND(AVERAGE(G32,H32)/1,0)*1 | J32: =IF($D32=0,"",I32/$D32) | K32: =IF(F32="","",IF(F32<G32,"POR DEBAJO",IF(F32>H32,"POR ENCIMA","EN MERCADO"))) | L32: D
A33: FITNESS | B33: BC | C33: BPC-157 | D33: 5 | E33: mg | F33: 20 | G33: =BANDAS!$E$27*$D33 | H33: =BANDAS!$F$27*$D33 | I33: =ROUND(AVERAGE(G33,H33)/1,0)*1 | J33: =IF($D33=0,"",I33/$D33) | K33: =IF(F33="","",IF(F33<G33,"POR DEBAJO",IF(F33>H33,"POR ENCIMA","EN MERCADO"))) | L33: V
A34: FITNESS | B34: BC | C34: BPC-157 | D34: 10 | E34: mg | F34: 35 | G34: =BANDAS!$E$27*$D34 | H34: =BANDAS!$F$27*$D34 | I34: =ROUND(AVERAGE(G34,H34)/1,0)*1 | J34: =IF($D34=0,"",I34/$D34) | K34: =IF(F34="","",IF(F34<G34,"POR DEBAJO",IF(F34>H34,"POR ENCIMA","EN MERCADO"))) | L34: V
A35: FITNESS | B35: BC | C35: BPC-157 | D35: 20 | E35: mg | F35: 75 | G35: =BANDAS!$E$27*$D35 | H35: =BANDAS!$F$27*$D35 | I35: =ROUND(AVERAGE(G35,H35)/1,0)*1 | J35: =IF($D35=0,"",I35/$D35) | K35: =IF(F35="","",IF(F35<G35,"POR DEBAJO",IF(F35>H35,"POR ENCIMA","EN MERCADO"))) | L35: V
A36: FITNESS | B36: BB | C36: BPC-157 + TB-500 | D36: 10 | E36: mg | F36: 35 | G36: =BANDAS!$E$28*$D36 | H36: =BANDAS!$F$28*$D36 | I36: =ROUND(AVERAGE(G36,H36)/1,0)*1 | J36: =IF($D36=0,"",I36/$D36) | K36: =IF(F36="","",IF(F36<G36,"POR DEBAJO",IF(F36>H36,"POR ENCIMA","EN MERCADO"))) | L36: D
A37: FITNESS | B37: BB | C37: BPC-157 + TB-500 | D37: 20 | E37: mg | F37: 75 | G37: =BANDAS!$E$28*$D37 | H37: =BANDAS!$F$28*$D37 | I37: =ROUND(AVERAGE(G37,H37)/1,0)*1 | J37: =IF($D37=0,"",I37/$D37) | K37: =IF(F37="","",IF(F37<G37,"POR DEBAJO",IF(F37>H37,"POR ENCIMA","EN MERCADO"))) | L37: D
A38: FITNESS | B38: CD | C38: CJC-1295 (DAC) | D38: 5 | E38: mg | F38: 44 | G38: =BANDAS!$E$29*$D38 | H38: =BANDAS!$F$29*$D38 | I38: =ROUND(AVERAGE(G38,H38)/1,0)*1 | J38: =IF($D38=0,"",I38/$D38) | K38: =IF(F38="","",IF(F38<G38,"POR DEBAJO",IF(F38>H38,"POR ENCIMA","EN MERCADO"))) | L38: D
A39: FITNESS | B39: CD | C39: CJC-1295 (DAC) | D39: 10 | E39: mg | F39: 82 | G39: =BANDAS!$E$29*$D39 | H39: =BANDAS!$F$29*$D39 | I39: =ROUND(AVERAGE(G39,H39)/1,0)*1 | J39: =IF($D39=0,"",I39/$D39) | K39: =IF(F39="","",IF(F39<G39,"POR DEBAJO",IF(F39>H39,"POR ENCIMA","EN MERCADO"))) | L39: D
A40: FITNESS | B40: CN | C40: CJC-1295 (no DAC) | D40: 5 | E40: mg | F40: 25 | G40: =BANDAS!$E$30*$D40 | H40: =BANDAS!$F$30*$D40 | I40: =ROUND(AVERAGE(G40,H40)/1,0)*1 | J40: =IF($D40=0,"",I40/$D40) | K40: =IF(F40="","",IF(F40<G40,"POR DEBAJO",IF(F40>H40,"POR ENCIMA","EN MERCADO"))) | L40: D
A41: FITNESS | B41: CN | C41: CJC-1295 (no DAC) | D41: 10 | E41: mg | F41: 50 | G41: =BANDAS!$E$30*$D41 | H41: =BANDAS!$F$30*$D41 | I41: =ROUND(AVERAGE(G41,H41)/1,0)*1 | J41: =IF($D41=0,"",I41/$D41) | K41: =IF(F41="","",IF(F41<G41,"POR DEBAJO",IF(F41>H41,"POR ENCIMA","EN MERCADO"))) | L41: D
A42: FITNESS | B42: CP | C42: CJC-1295 + Ipamorelin | D42: 10 | E42: mg | F42: 50 | G42: =BANDAS!$E$31*$D42 | H42: =BANDAS!$F$31*$D42 | I42: =ROUND(AVERAGE(G42,H42)/1,0)*1 | J42: =IF($D42=0,"",I42/$D42) | K42: =IF(F42="","",IF(F42<G42,"POR DEBAJO",IF(F42>H42,"POR ENCIMA","EN MERCADO"))) | L42: V
...

Sheet BANDAS
B2: BANDAS DE MERCADO
B3: Precio de mercado por unidad, en dólares. Es el único sitio donde hay números escritos a mano: todo lo demás del libro sale de aquí por fórmula.
B5: Tipo de cambio USD → MXN | E5: 17.5 | F5: Fuente: Investing.com · media 2026 ≈ 17.47
B6: Prima del retail mexicano sobre el estadounidense | E6: 1.35 | F6: Mediana observada comparando ocho pares MX/USA reales (ver FUENTES)
A8: CÓDIGO | B8: COMPUESTO | C8: LÍNEA | D8: UNIDAD | E8: USD/UNIDAD BAJO | F8: USD/UNIDAD ALTO | G8: CONF. | H8: DE DÓNDE SALE
A9: AC | B9: AHK-Cu | C9: BEAUTY | D9: mg | E9: 0.7 | F9: 1.3 | G9: D | H9: AHK-Cu: 50 mg $35–65, sigue a GHK-Cu con prima
A10: CU | B10: GHK-Cu | C10: BEAUTY | D10: mg | E10: 0.5 | F10: 0.8 | G10: V | H10: peptide.promo · GHK-Cu desde $0.50/mg; 50 mg $20–40
A11: GL | B11: GLOW Blend | C11: BEAUTY | D11: mg | E11: 1.7 | F11: 3.1 | G11: D | H11: Mezcla GLOW 70 mg: $120–220 el vial
A12: GT | B12: Glutathione | C12: BEAUTY | D12: mg | E12: 0.05 | F12: 0.1 | G12: D | H12: Glutatión: 600 mg $30–60, es materia prima
A13: KL | B13: KLOW Blend | C13: BEAUTY | D13: mg | E13: 1.9 | F13: 3.25 | G13: D | H13: Mezcla KLOW 80 mg: $150–260 el vial
A14: KP | B14: KPV | C14: BEAUTY | D14: mg | E14: 3 | F14: 5.5 | G14: D | H14: KPV: 10 mg $30–55
A15: MX | B15: Matrixyl | C15: BEAUTY | D15: mg | E15: 5 | F15: 9 | G15: D | H15: Matrixyl: 10 mg $50–90
A16: MT1 | B16: Melanotan I | C16: BEAUTY | D16: mg | E16: 3 | F16: 5.5 | G16: D | H16: Melanotán 1: sigue a melanotán 2 con menos demanda
A17: MT2 | B17: Melanotan II | C17: BEAUTY | D17: mg | E17: 2.2 | F17: 6.4 | G17: V | H17: nationwidepeptides · melanotán 2 $22–30 y $47–64 según presentación
A18: OT | B18: Oxytocin | C18: BEAUTY | D18: mg | E18: 5 | F18: 9 | G18: D | H18: Oxitocina: 5 mg $25–45
A19: PT | B19: PT-141 | C19: BEAUTY | D19: mg | E19: 4 | F19: 8 | G19: V | H19: biotechpeptides / nexaph · PT-141 10 mg; nexaph $160 es el techo del mercado
A20: NP8 | B20: Snap-8 | C20: BEAUTY | D20: mg | E20: 3 | F20: 5.5 | G20: D | H20: Snap-8: 10 mg $30–55
... A64: B12 | B64: Vitamin B12 | C64: LONGEVITY | D64: mg | E64: 15 | F64: 30 | G64: D | H64: Vitamina B12 por vial de 1 mg/ml: $15–30

Sheet FUENTES
B2: FUENTES
B3: Cada enlace consultado y qué dato salió de él. Consultado el 02.08.2026. Los precios de este mercado se mueven semana a semana: conviene volver cada trimestre.
A5: MERCADO | B5: FUENTE | C5: QUÉ DATO DIO | D5: ENLACE
A6: USA | B6: peptide.promo | C6: Comparador $/mg. Semaglutida $2.75/mg · tirzepatida $3.09/mg · BPC-157 $2.46/mg · GHK-Cu $0.50/mg · NAD+ $0.14/mg | D6: https://peptide.promo/
A7: USA | B7: PeptidesExplorer | C7: Rangos por vial: semaglutida 5 mg $20–40 · tirzepatida 5 mg $20–45 · retatrutida 5 mg $24–50 · BPC-157 5 mg $20–35 · GHK-Cu 50 mg $20–40 | D7: https://peptidesexplorer.com/blog/how-much-do-peptides-cost
A8: USA | B8: PeptiLab Research | C8: BPC-157 10 mg $22.79 · TB-500 10 mg $29.99 · epitalón 10 mg $13.79 · retatrutida 10 mg $56.40 (con descuento) | D8: https://peptilabresearch.com/shop/
A9: USA | B9: peptideprices.net | C9: Comparador $/10 mg sobre 51 vendedores, con COA y fecha de comprobación por listado | D9: https://peptideprices.net/
A10: USA | B10: PepsTracker | C10: Comparador sobre 24 vendedores; volatilidad semanal de tirzepatida y retatrutida | D10: https://pepstracker.com/
A11: USA | B11: The Peptide Catalog | C11: Índice de precios trimestral, tendencia a 90 días | D11: https://thepeptidecatalog.com/articles/peptide-pricing-report-q1-2026
A12: USA | B12: PeptideDeck | C12: BPC-157 $49–100 por vial en 2026; $5–8/mg de vendedor legítimo; por debajo de $3/mg es señal de alarma | D12: https://www.peptidedeck.com/blog/bpc-157-for-sale
A13: USA | B13: Biotech Peptides | C13: Precio de lista de BPC-157 5 mg y mezcla CJC-1295 + Ipamorelina 10 mg | D13: https://biotechpeptides.com/product/bpc-157/
A14: USA | B14: Nationwide Peptides | C14: Melanotán 2: $22–30 y $47–64 según presentación | D14: https://www.nationwidepeptides.com/products/melanotan-2/
A15: USA | B15: NEXAPH | C15: PT-141 $160 — techo del mercado, útil como referencia superior | D15: https://nexaph.com/
A16: USA | B16: Peptide Pros | C16: Catálogo de secretagogos GH: GHRP-2 5 mg, GHRP-6 5 mg, hexarelina 2 mg, ipamorelina 2 mg, sermorelina 2 mg, tesamorelina 5 mg | D16: https://www.peptidepros.net/
... A26: Tipo de cambio | B26: Investing.com | C26: USD/MXN 17.35 al cierre consultado; media 2026 ≈ 17.47. En el libro se usa 17.50 | D26: https://es.investing.com/currencies/usd-mxn-historical-data
B28: NOTA SOBRE EL MÉTODO
B29: · El acceso directo a las tiendas está bloqueado desde este entorno, así que los precios se han triangulado con buscador sobre varios comparadores y fichas de producto en lugar de leerse de la tienda una por una.
B30: · Por eso el libro separa V de D en vez de dar todo por igual: donde hay una cifra publicada para ese compuesto se marca V; donde no la hay, se usa la banda de su clase y se marca D.
B31: · Antes de fijar precio en los diez compuestos que más vendas, conviene abrir esos enlaces y confirmar el número del día. Son diez comprobaciones, no ciento dieciocho.
